#VRML_SIM R2023b utf8

EXTERNPROTO "https://raw.githubusercontent.com/cyberbotics/webots/R2023b/projects/objects/backgrounds/protos/TexturedBackground.proto"
EXTERNPROTO "https://raw.githubusercontent.com/cyberbotics/webots/R2023b/projects/objects/backgrounds/protos/TexturedBackgroundLight.proto"
EXTERNPROTO "https://raw.githubusercontent.com/cyberbotics/webots/R2023b/projects/objects/floors/protos/RectangleArena.proto"
EXTERNPROTO "https://raw.githubusercontent.com/cyberbotics/webots/R2023b/projects/appearances/protos/FormedConcrete.proto"

WorldInfo {
}
Viewpoint {
  orientation 0.09276513264508952 0.0045138372638207904 -0.9956777869564505 3.0447409660488836
  position 38.25263883387586 10.91727106088075 18.254189453226747
}
TexturedBackground {
}
TexturedBackgroundLight {
}
RectangleArena {
  floorSize 20 20
  floorAppearance FormedConcrete {
  }
}
DEF Almacen Group {
  children [
    DEF Estanterias Group {
      children [
        Solid {
          translation -11.21 6.58 1.25021e-05
          rotation -1.2264404877024328e-06 0.7071072811860378 0.7071062811856401 -3.1415853071795863
          children [
            DEF estante Shape {
              appearance PBRAppearance {
              }
              geometry Mesh {
                url [
                  "../3d objects/Metal-Shelf.obj"
                ]
              }
              castShadows FALSE
            }
          ]
          boundingObject USE estante
        }
        Solid {
          translation 1.51 4.9401 -2.9193e-05
          rotation -1.2264404877024328e-06 0.7071072811860378 0.7071062811856401 -3.1415853071795863
          children [
            Shape {
              appearance PBRAppearance {
              }
              geometry Mesh {
                url [
                  "../3d objects/Metal-Shelf.obj"
                ]
              }
              castShadows FALSE
            }
          ]
          name "solid(8)"
          boundingObject USE estante
        }
        Solid {
          translation -1.33 8.42 -2.42864e-05
          rotation 0.9999999999850366 5.189909999922341e-06 1.7296599999741186e-06 1.57079
          children [
            Shape {
              appearance PBRAppearance {
              }
              geometry Mesh {
                url [
                  "../3d objects/Metal-Shelf.obj"
                ]
              }
              castShadows FALSE
            }
          ]
          name "solid(3)"
          boundingObject USE estante
        }
        Solid {
          translation 1.58 8.56 -3.45539e-05
          rotation -1.2264404877024328e-06 0.7071072811860378 0.7071062811856401 -3.1415853071795863
          children [
            Shape {
              appearance PBRAppearance {
              }
              geometry Mesh {
                url [
                  "../3d objects/Metal-Shelf.obj"
                ]
              }
              castShadows FALSE
            }
          ]
          name "solid(6)"
          boundingObject USE estante
        }
        Solid {
          translation 1.58 8.56 -3.45539e-05
          rotation -1.2264404877024328e-06 0.7071072811860378 0.7071062811856401 -3.1415853071795863
          children [
            Shape {
              appearance PBRAppearance {
              }
              geometry Mesh {
                url [
                  "../3d objects/Metal-Shelf.obj"
                ]
              }
              castShadows FALSE
            }
          ]
          name "solid(12)"
          boundingObject USE estante
        }
        Solid {
          translation 1.58004 -8.21 -1.08377e-05
          rotation -1.2264404877024328e-06 0.7071072811860378 0.7071062811856401 -3.1415853071795863
          children [
            Shape {
              appearance PBRAppearance {
              }
              geometry Mesh {
                url [
                  "../3d objects/Metal-Shelf.obj"
                ]
              }
              castShadows FALSE
            }
          ]
          name "solid(14)"
          boundingObject USE estante
        }
        Solid {
          translation -11.51 -8.21004 3.44565e-05
          rotation -1.2264404877024328e-06 0.7071072811860378 0.7071062811856401 -3.1415853071795863
          children [
            Shape {
              appearance PBRAppearance {
              }
              geometry Mesh {
                url [
                  "../3d objects/Metal-Shelf.obj"
                ]
              }
              castShadows FALSE
            }
          ]
          name "solid(15)"
          boundingObject USE estante
        }
        Solid {
          translation 11.52 -4.69994 -5.96543e-05
          rotation 0.9999999999850531 5.189909999922427e-06 1.7200699999742903e-06 1.57079
          children [
            Shape {
              appearance PBRAppearance {
              }
              geometry Mesh {
                url [
                  "../3d objects/Metal-Shelf.obj"
                ]
              }
              castShadows FALSE
            }
          ]
          name "solid(18)"
          boundingObject USE estante
        }
        Solid {
          translation -1.59 -4.70003 -1.41646e-05
          rotation 0.9999999999850531 5.189909999922427e-06 1.7200699999742903e-06 1.57079
          children [
            Shape {
              appearance PBRAppearance {
              }
              geometry Mesh {
                url [
                  "../3d objects/Metal-Shelf.obj"
                ]
              }
              castShadows FALSE
            }
          ]
          name "solid(19)"
          boundingObject USE estante
        }
      ]
    }
    DEF Paredes Group {
      children [
        DEF Pared Solid {
          translation 0 -10 7.5
          rotation 0 0 1 3.14159
          children [
            DEF pared_shape Shape {
              appearance PBRAppearance {
                baseColorMap ImageTexture {
                  url [
                    "../Textures/Concrete.jpg"
                  ]
                }
              }
              geometry Box {
                size 20 0.1 15
              }
            }
          ]
          name "solid(2)"
          boundingObject USE pared_shape
        }
        DEF Pared Solid {
          translation 1.31881e-05 10 7.5
          rotation 0 0 1 3.14159
          children [
            DEF pared_shape Shape {
              appearance PBRAppearance {
                baseColorMap ImageTexture {
                  url [
                    "../Textures/Concrete.jpg"
                  ]
                }
              }
              geometry Box {
                size 20 0.1 15
              }
            }
          ]
          name "solid(1)"
          boundingObject USE pared_shape
        }
        DEF Pared Solid {
          translation -10 -8.40165e-06 7.5
          rotation 0 0 1 -1.5707953071795862
          children [
            DEF pared_shape Shape {
              appearance PBRAppearance {
                baseColorMap ImageTexture {
                  url [
                    "../Textures/Concrete.jpg"
                  ]
                }
              }
              geometry Box {
                size 20 0.1 15
              }
            }
          ]
          name "solid(4)"
          boundingObject USE pared_shape
        }
      ]
    }
  ]
}
Robot {
  rotation 0 1 0 0.261799
  children [
    Receiver {
    }
  ]
  name "supervisor"
  controller "sup_controller_py"
  supervisor TRUE
}
DEF RobotCam1 Robot {
  translation 0.1 0 0.1
  children [
    Camera {
      name "camara1"
    }
    Emitter {
      name "emitter1"
    }
  ]
  controller "camera1"
}
DEF RobotCam2 Robot {
  translation 0.2 0 0.2
  children [
    Camera {
      name "camara2"
    }
    Emitter {
      name "emitter2"
    }
  ]
  name "robot(1)"
  controller "camera2"
}
Robot {
  translation -3.5247260324669455e-17 2.162635161803585e-17 0.12460767418210678
  rotation 7.703977778775088e-18 4.147301768583906e-17 1 3.14159
  children [
    DEF ds_left DistanceSensor {
      translation 0.499119 0.153292 0
      rotation 0 0 1 0.261794
      children [
        DEF sensor Shape {
          appearance PBRAppearance {
            baseColor 0 0 1
            metalness 0
          }
          geometry Box {
            size 0.05 0.05 0.05
          }
        }
      ]
      name "ds_left"
      boundingObject USE sensor
    }
    DEF ds_right DistanceSensor {
      translation 0.5134 -0.146411 0
      rotation 0 0 -1 0.261796
      children [
        DEF sensor Shape {
          appearance PBRAppearance {
            baseColor 0 0 1
            metalness 0
          }
          geometry Box {
            size 0.05 0.05 0.05
          }
        }
      ]
      name "ds_right"
      boundingObject USE sensor
    }
    HingeJoint {
      jointParameters HingeJointParameters {
        position 2.3639040000000016
        axis 0 1 0
        anchor 0.25 0.3 0
      }
      device [
        RotationalMotor {
          name "wheel1"
          acceleration 1
        }
      ]
      endPoint Solid {
        translation 0.25 0.3 0
        rotation 0.27826346398027574 0.6791782004109472 -0.679180695176361 2.5987991733768343
        children [
          DEF Wheel Shape {
            appearance PBRAppearance {
              baseColor 0 1 0
              metalness 0
            }
            geometry Cylinder {
              height 0.1
              radius 0.2
            }
          }
        ]
        boundingObject USE Wheel
      }
    }
    HingeJoint {
      jointParameters HingeJointParameters {
        position 2.3639040000000016
        axis 0 1 0
        anchor 0.25 -0.3 0
      }
      device [
        RotationalMotor {
          name "wheel2"
          acceleration 1
        }
      ]
      endPoint Solid {
        translation 0.25 -0.3 0
        rotation 0.27826346398027574 0.6791782004109472 -0.679180695176361 2.5987991733768343
        children [
          USE Wheel
        ]
        boundingObject USE Wheel
      }
    }
    HingeJoint {
      jointParameters HingeJointParameters {
        position 2.3639040000000016
        axis 0 1 0
        anchor -0.25 0.3 0
      }
      device [
        RotationalMotor {
          name "wheel3"
          acceleration 1
        }
      ]
      endPoint Solid {
        translation -0.25 0.3 0
        rotation 0.27826346398027574 0.6791782004109472 -0.679180695176361 2.5987991733768343
        children [
          USE Wheel
        ]
        boundingObject USE Wheel
      }
    }
    HingeJoint {
      jointParameters HingeJointParameters {
        position 2.3639040000000016
        axis 0 1 0
        anchor -0.25 -0.3 0
      }
      device [
        RotationalMotor {
          name "wheel4"
          acceleration 1
        }
      ]
      endPoint Solid {
        translation -0.25 -0.3 0
        rotation 0.27826346398027574 0.6791782004109472 -0.679180695176361 2.5987991733768343
        children [
          USE Wheel
        ]
        boundingObject USE Wheel
      }
    }
    DEF Body Shape {
      appearance PBRAppearance {
        baseColor 1 0 0
        metalness 0
      }
      geometry Box {
        size 1 0.5 0.25
      }
    }
  ]
  boundingObject USE Body
  physics Physics {
    mass 1
  }
  controller "thief_robot"
  linearVelocity 9.195610806500928e-19 1.651174807132046e-17 -5.809695716718644e-07
  angularVelocity -1.0221568339640243e-21 1.6049906502146443e-16 -5.1965724339462945e-18
}
