#VRML_SIM R2023b utf8
PROTO FourWheelsRobot [
  field SFVec3f    translation  0 0 0
  field SFRotation rotation     0 0 1 0
  field SFFloat    bodyMass     1
]
{
    Robot {
      translation IS translation
      rotation IS rotation
      children [
        DEF ds_left DistanceSensor {
          translation 0.0998238 0.0306583 0
          rotation 0 0 1 0.261794
          children [
            DEF sensor Shape {
              appearance PBRAppearance {
                baseColor 0 0 1
                metalness 0
              }
              geometry Box {
                size 0.01 0.01 0.01
              }
            }
          ]
          name "ds_left"
          boundingObject USE sensor
          physics Physics {
          }
        }
        DEF ds_right DistanceSensor {
          translation 0.10268 -0.0292822 0
          rotation 0 0 -1 0.261796
          children [
            DEF sensor Shape {
              appearance PBRAppearance {
                baseColor 0 0 1
                metalness 0
              }
              geometry Box {
                size 0.01 0.01 0.01
              }
            }
          ]
          name "ds_right"
          boundingObject USE sensor
          physics Physics {
          }
        }
        HingeJoint {
          jointParameters HingeJointParameters {
            axis 0 1 0
            anchor 0.05 0.06 0
          }
          device [
            RotationalMotor {
              name "wheel1"
              acceleration 1
            }
          ]
          endPoint Solid {
            translation 0.05 0.06 0
            rotation 1 0 0 1.5708
            children [
              DEF Wheel Shape {
                appearance PBRAppearance {
                  baseColor 0 1 0
                  metalness 0
                }
                geometry Cylinder {
                  height 0.02
                  radius 0.04
                }
              }
            ]
            name "solid(4)"
            boundingObject USE Wheel
            physics DEF Physics_wh Physics {
            }
          }
        }
        HingeJoint {
          jointParameters HingeJointParameters {
            axis 0 1 0
            anchor 0.05 -0.06 0
          }
          device [
            RotationalMotor {
              name "wheel2"
              acceleration 1
            }
          ]
          endPoint Solid {
            translation 0.05 -0.06 0
            rotation 1 0 0 1.5708
            children [
              USE Wheel
            ]
            boundingObject USE Wheel
            physics USE Physics_wh
          }
        }
        HingeJoint {
          jointParameters HingeJointParameters {
            axis 0 1 0
            anchor -0.05 0.06 0
          }
          device [
            RotationalMotor {
              name "wheel3"
              acceleration 1
            }
          ]
          endPoint Solid {
            translation -0.05 0.06 0
            rotation 1 0 0 1.5708
            children [
              USE Wheel
            ]
            name "solid(1)"
            boundingObject USE Wheel
            physics USE Physics_wh
          }
        }
        HingeJoint {
          jointParameters HingeJointParameters {
            axis 0 1 0
            anchor -0.05 -0.06 0
          }
          device [
            RotationalMotor {
              name "wheel4"
              acceleration 1
            }
          ]
          endPoint Solid {
            translation -0.05 -0.06 0
            rotation 1 0 0 1.5708
            children [
              USE Wheel
            ]
            name "solid(2)"
            boundingObject USE Wheel
            physics USE Physics_wh
          }
        }
        DEF Body Shape {
          appearance PBRAppearance {
            baseColor 1 0 0
            metalness 0
          }
          geometry Box {
            size 0.2 0.1 0.05
          }
        }
      ]
      boundingObject USE Body
      physics Physics {
        mass IS bodyMass
      }
      controller "4_wheels_c"
    }
}
