#VRML_SIM R2023b utf8

EXTERNPROTO "https://raw.githubusercontent.com/cyberbotics/webots/R2023b/projects/objects/backgrounds/protos/TexturedBackground.proto"
EXTERNPROTO "https://raw.githubusercontent.com/cyberbotics/webots/R2023b/projects/objects/backgrounds/protos/TexturedBackgroundLight.proto"
EXTERNPROTO "https://raw.githubusercontent.com/cyberbotics/webots/R2023b/projects/objects/floors/protos/RectangleArena.proto"

WorldInfo {
  basicTimeStep 16
}
Viewpoint {
  orientation 0.4678278260228206 -0.8837311061517317 -0.012508285997622784 5.44789962677558
  position -1.4107100288348202 -0.03603634647708749 0.8241419220878329
}
TexturedBackground {
}
TexturedBackgroundLight {
}
RectangleArena {
  floorTileSize 0.25 0.25
}
DEF Wall_1 Solid {
  translation 0.52 0 0
  children [
    DEF Wall Shape {
      appearance Appearance {
        material Material {
        }
        texture ImageTexture {
          url [
            ""
            ""
            ""
            ""
          ]
        }
      }
      geometry Box {
        size 0.12 1.1 0.25
      }
    }
  ]
  name "solid(1)"
}
DEF Wall_2 Solid {
  translation 0.0099995 0.49 0
  rotation 0 0 1 -1.5707953071795862
  children [
    USE Wall
  ]
  name "solid(2)"
}
DEF Wall_3 Solid {
  translation -0.5 0 0
  children [
    USE Wall
  ]
  name "solid(3)"
}
DEF Wall_4 Solid {
  translation 4.99606e-07 -0.49 0
  rotation 0 0 1 -1.5707953071795862
  children [
    USE Wall
  ]
  name "solid(4)"
}
Robot {
  translation 0 0 0.08
  rotation 0 0 1 3.14159
  children [
    DEF ds_left DistanceSensor {
      translation 0.0998238 0.0306583 0
      rotation 0 0 1 0.261794
      children [
        DEF sensor Shape {
          appearance PBRAppearance {
            baseColor 0 0 1
            metalness 0
          }
          geometry Box {
            size 0.01 0.01 0.01
          }
        }
      ]
      name "ds_left"
      boundingObject USE sensor
      physics Physics {
      }
    }
    DEF ds_right DistanceSensor {
      translation 0.10268 -0.0292822 0
      rotation 0 0 -1 0.261796
      children [
        DEF sensor Shape {
          appearance PBRAppearance {
            baseColor 0 0 1
            metalness 0
          }
          geometry Box {
            size 0.01 0.01 0.01
          }
        }
      ]
      name "ds_right"
      boundingObject USE sensor
      physics Physics {
      }
    }
    HingeJoint {
      jointParameters HingeJointParameters {
        axis 0 1 0
        anchor 0.05 0.06 0
      }
      device [
        RotationalMotor {
          name "wheel1"
          acceleration 1
        }
      ]
      endPoint Solid {
        translation 0.05 0.06 0
        rotation 1 0 0 1.5708
        children [
          DEF Wheel Shape {
            appearance PBRAppearance {
              baseColor 0 1 0
              metalness 0
            }
            geometry Cylinder {
              height 0.02
              radius 0.04
            }
          }
        ]
        name "solid(4)"
        boundingObject USE Wheel
        physics DEF Physics_wh Physics {
        }
      }
    }
    HingeJoint {
      jointParameters HingeJointParameters {
        axis 0 1 0
        anchor 0.05 -0.06 0
      }
      device [
        RotationalMotor {
          name "wheel2"
          acceleration 1
        }
      ]
      endPoint Solid {
        translation 0.05 -0.06 0
        rotation 1 0 0 1.5708
        children [
          USE Wheel
        ]
        boundingObject USE Wheel
        physics USE Physics_wh
      }
    }
    HingeJoint {
      jointParameters HingeJointParameters {
        axis 0 1 0
        anchor -0.05 0.06 0
      }
      device [
        RotationalMotor {
          name "wheel3"
          acceleration 1
        }
      ]
      endPoint Solid {
        translation -0.05 0.06 0
        rotation 1 0 0 1.5708
        children [
          USE Wheel
        ]
        name "solid(1)"
        boundingObject USE Wheel
        physics USE Physics_wh
      }
    }
    HingeJoint {
      jointParameters HingeJointParameters {
        axis 0 1 0
        anchor -0.05 -0.06 0
      }
      device [
        RotationalMotor {
          name "wheel4"
          acceleration 1
        }
      ]
      endPoint Solid {
        translation -0.05 -0.06 0
        rotation 1 0 0 1.5708
        children [
          USE Wheel
        ]
        name "solid(2)"
        boundingObject USE Wheel
        physics USE Physics_wh
      }
    }
    DEF Body Shape {
      appearance PBRAppearance {
        baseColor 1 0 0
        metalness 0
      }
      geometry Box {
        size 0.2 0.1 0.05
      }
    }
  ]
  boundingObject USE Body
  physics Physics {
    mass 1
  }
  controller "4_wheels_c"
}
